<?xml version="1.0"?>

<robot xmlns:xacro="http://www.ros.org/wiki/xacro" name="avu">

  <xacro:include filename="$(find avu_description)/urdf/avu_gazebo.xacro" />
  <xacro:include filename="$(find avu_description)/urdf/avu_ros_control.xacro" />

    <xacro:property name="M_PI" value="3.1415926535897931" />

    <xacro:property name="d435_cam_width" value="0.090"/>
    <xacro:property name="d435_cam_height" value="0.025"/>
    <xacro:property name="d435_cam_depth" value="0.02505"/>

    <xacro:property name="d435_cam_depth_to_infra1_offset" value="0.0"/>
    <xacro:property name="d435_cam_depth_to_infra2_offset" value="-0.050"/>
    <xacro:property name="d435_cam_depth_to_color_offset" value="0.015"/>

    <xacro:property name="joint_effort" value="56.0"/>
    <xacro:property name="joint_velocity" value="2.792527"/>
    <xacro:property name="joint_damping" value="0.0"/>
    <xacro:property name="joint_friction" value="0.0"/>

    <xacro:property name="link1_mass" value="0.12"/>
    <xacro:property name="link2_mass" value="0.19"/>
    <xacro:property name="link3_mass" value="0.16"/>
    <xacro:property name="link4_mass" value="0.124"/>
    <xacro:property name="link5_mass" value="0.11"/>
    <xacro:property name="link6_mass" value="0.0739"/>
    <xacro:property name="flange_mass" value="0.035"/>

    <xacro:property name="joint_effort" value="56.0"/>
    <xacro:property name="joint_velocity" value="2.792527"/>
    <xacro:property name="joint_damping" value="0.0"/>
    <xacro:property name="joint_friction" value="0.0"/>

    <xacro:property name="gripper_link_mass" value="0.007"/>
    <xacro:property name="gripper_link_ixx" value="1e-6"/>
    <xacro:property name="gripper_link_iyy" value="1e-6"/>
    <xacro:property name="gripper_link_izz" value="1e-6"/>

    <xacro:macro name="link_inertial" params="mass ixx iyy izz">
        <inertial>
          <origin xyz="0 0 0.0" rpy="0 0 0"/>
          <mass value="${mass}"/>
          <inertia
              ixx="${ixx}" ixy="0.0" ixz="0.0"
              iyy="${iyy}" iyz="0.0"
              izz="${izz}"/>
        </inertial>
    </xacro:macro>

    <xacro:macro name="gripper_link_inertial">
      <inertial>
        <origin xyz="0 0 0.0" rpy="0 0 0"/>
        <mass value="${gripper_link_mass}"/>
        <inertia
          ixx="${gripper_link_ixx}" ixy="0.0" ixz="0.0"
          iyy="${gripper_link_iyy}" iyz="0.0"
          izz="${gripper_link_izz}"/>
      </inertial>
    </xacro:macro>

    <xacro:macro name="material_visual" params="ref_link ambient diffuse specular">
        <gazebo reference="${ref_link}">
        <visual>
            <material>
            <ambient>${ambient}</ambient>
            <diffuse>${diffuse}</diffuse>
            <specular>${specular}</specular>
            </material>
        </visual>
        </gazebo>
    </xacro:macro>

    <link name="world"/>

    <link name="base_link">
            <inertial>
                <origin xyz="0 0 0.0" rpy="0 0 0"/>
                <mass value="0.33"/>
                <inertia
                    ixx="0.000784" ixy="0.0" ixz="0.0"
                    iyy="0.000867" iyz="0.0"
                    izz="0.001598"/>
            </inertial>
            <visual>
                <geometry>
                    <mesh filename="package://avu_description/meshes/base_link.dae"/>
                </geometry>
                <origin xyz="0.0 0 -0.03" rpy="0 0 ${pi/2}"/>
            </visual>
            <collision>
                <geometry>
                    <box size="0.105 0.14 0.02"/>
                </geometry>
                <origin xyz="0.0 0.0 -0.015" rpy="0 0 0"/>
            </collision>
    </link>


    <link name="link1">
      <xacro:link_inertial mass="${link1_mass}" ixx="0.000148" iyy="0.000148" izz="0.000096"/>
      <visual>
        <geometry>
          <mesh filename="package://avu_description/meshes/link1.dae"/>
        </geometry>
        <origin xyz="0.0 0 0" rpy="0 0 ${-pi/2}"/>
      </visual>
      <collision>
        <geometry>
          <box size="0.08 0.12 0.075"/>
        </geometry>
        <origin xyz="0.0 -0.01 0.034" rpy="0 0 0"/>
      </collision>
    </link>

    <link name="link2">
      <xacro:link_inertial mass="${link2_mass}" ixx="0.000148" iyy="0.000148" izz="0.000096"/>
      <visual>
        <geometry>
          <mesh filename="package://avu_description/meshes/link2.dae"/>
        </geometry>
        <origin xyz="0.0 0 -0.06096" rpy="0 0 ${-pi/2}"/>
      </visual>
      <collision>
        <geometry>
          <cylinder radius="0.025" length="0.085"/>
        </geometry>
        <origin xyz="0.0 0 -0.02" rpy="0 0 ${-pi/2}"/>
      </collision>
    </link>

    <link name="link3">
      <xacro:link_inertial mass="${link3_mass}" ixx="0.000148" iyy="0.000148" izz="0.000096"/>
      <visual>
        <geometry>
          <mesh filename="package://avu_description/meshes/link3.dae"/>
        </geometry>
        <origin xyz="0.0 0 0.03256" rpy="0 ${-pi/2} 0"/>
      </visual>
      <collision>
        <geometry>
          <cylinder radius="0.025" length="0.15"/>
        </geometry>
        <origin xyz="-0.058 0 0.059" rpy="0 ${-pi/2} 0"/>
      </collision>
    </link>

    <link name="link4">
      <xacro:link_inertial mass="${link4_mass}" ixx="0.000103" iyy="0.000103" izz="0.000096"/>
      <visual>
        <geometry>
          <mesh filename="package://avu_description/meshes/link4.dae"/>
        </geometry>
        <origin xyz="0.0 0 0.03056" rpy="0 ${-pi/2} 0"/>
      </visual>
      <collision>
        <geometry>
          <cylinder radius="0.025" length="0.125"/>
        </geometry>
        <origin xyz="-0.05 0 0.0" rpy="0 ${-pi/2} 0"/>
      </collision>
    </link>

    <link name="link5">
      <xacro:link_inertial mass="${link5_mass}" ixx="0.000103" iyy="0.000103" izz="0.000096"/>
      <visual>
        <geometry>
          <mesh filename="package://avu_description/meshes/link5.dae"/>
        </geometry>
        <origin xyz="0.0 0 -0.03356" rpy="${-pi/2} 0 0"/>
      </visual>
      <collision>
        <geometry>
          <box size="0.03 0.035 0.05"/>
        </geometry>
        <origin xyz="0.0 0 -0.005" rpy="0 0.0 0"/>
      </collision>
    </link>

    <link name="link6">
      <xacro:link_inertial mass="${link6_mass}" ixx="0.00006649" iyy="0.00006649" izz="0.000096"/>
      <visual>
        <geometry>
          <mesh filename="package://avu_description/meshes/link6.dae"/>
        </geometry>
        <origin xyz="0 0.00 -0.038" rpy="0 0 0"/>
      </visual>
      <collision>
        <geometry>
          <cylinder radius="0.025" length="0.06"/>
        </geometry>
        <origin xyz="0 0.00 0.0" rpy="${-pi/2} 0 0"/>
      </collision>
    </link>

    <link name="flange_link">
      <xacro:link_inertial mass="${flange_mass}" ixx="0.0000149" iyy="0.0000149" izz="0.0000196"/>
      <visual>
        <geometry>
          <mesh filename="package://avu_description/meshes/link7.dae"/>
        </geometry>
        <origin xyz="0.0 0 -0.012" rpy="0 0 0"/>
      </visual>
      <collision>
        <geometry>
          <cylinder radius="0.02" length="0.02"/>
        </geometry>
        <origin xyz="0 0.00 0.0" rpy="0 0 0"/>
      </collision>
    </link>

    <joint name="virtual" type="fixed">
        <parent link="world"/>
        <child link="base_link"/>
        <origin xyz="0 0 0" rpy="0 0 0"/>
    </joint> 

    <joint name="base_link_to_link1" type="fixed">
      <parent link="base_link"/>
      <child link="link1"/>
      <origin xyz="0 0 0" rpy="0 0 0"/>
    </joint>

    <joint name="joint_1" type="revolute">
      <axis xyz="0 0 1"/>
      <limit effort="${joint_effort}" lower="-2.879793" upper="2.879793" velocity="${joint_velocity}"/>
      <parent link="link1"/>
      <child link="link2"/>
      <origin xyz="0 0 0.13156" rpy="0 0 ${pi/2}"/>
      <dynamics damping="${joint_damping}" friction="${joint_friction}"/>
    </joint>

    <joint name="joint_2" type="revolute">
      <axis xyz="0 0 1"/>
      <limit effort="${joint_effort}" lower="-2.879793" upper="2.879793" velocity="${joint_velocity}"/>
      <parent link="link2"/>
      <child link="link3"/>
      <origin xyz="0 0 -0.001" rpy="0 ${pi/2} ${-pi/2}"/>
      <dynamics damping="${joint_damping}" friction="${joint_friction}"/>
    </joint>

    <joint name="joint_3" type="revolute">
      <axis xyz="0 0 1"/>
      <limit effort="${joint_effort}" lower="-2.879793" upper="2.879793" velocity="${joint_velocity}"/>
      <parent link="link3"/>
      <child link="link4"/>
      <origin xyz="-0.1104 0 0" rpy="0 0 0"/>
      <dynamics damping="${joint_damping}" friction="${joint_friction}"/>
    </joint>

    <joint name="joint_4" type="revolute">
      <axis xyz="0 0 1"/>
      <limit effort="${joint_effort}" lower="-2.879793" upper="2.879793" velocity="${joint_velocity}"/>
      <parent link="link4"/>
      <child link="link5"/>
      <origin xyz="-0.096 0 0.06062" rpy="0 0 ${-pi/2}"/>
      <dynamics damping="${joint_damping}" friction="${joint_friction}"/>
    </joint>

    <joint name="joint_5" type="revolute">
      <axis xyz="0 0 1"/>
      <limit effort="${joint_effort}" lower="-2.879793" upper="2.879793" velocity="${joint_velocity}"/>
      <parent link="link5"/>
      <child link="link6"/>
      <origin xyz="0 -0.07318 0" rpy="${pi/2} ${-pi/2} 0"/>
      <dynamics damping="${joint_damping}" friction="${joint_friction}"/>
    </joint>

    <joint name="joint_6" type="revolute">
      <axis xyz="0 0 1"/>
      <limit effort="${joint_effort}" lower="-3.05" upper="3.05" velocity="${joint_velocity}"/>
      <parent link="link6"/>
      <child link="flange_link"/>
      <origin xyz="0 0.0456 0" rpy="${-pi/2} 0 0"/>
      <dynamics damping="${joint_damping}" friction="${joint_friction}"/>
    </joint>

    <link name="gripper_base">
      <inertial>
        <origin xyz="0 0 0.0" rpy="0 0 0"/>
        <mass value="0.07"/>
        <inertia
          ixx="0.000010725" ixy="0.0" ixz="0.0"
          iyy="0.000014392" iyz="0.0"
          izz="0.000018517"/>
      </inertial>
      <visual>
        <geometry>
          <mesh filename="package://avu_description/meshes/gripper_base.dae"/>
        </geometry>
        <origin xyz="0.0 0.0 -0.012" rpy="0 0 0"/>
      </visual>
      <collision>
        <geometry>
          <box size="0.065 0.025 0.025"/>
        </geometry>
        <origin xyz="0.0 0.0 0.0" rpy="0 0 0"/>
      </collision>
    </link>

    <link name='camera_link'>
      <pose>0 0 0 0 0 0</pose>
      <collision>
        <origin xyz="0 0 0" rpy="0 0 0"/> 
        <geometry>
          <box size=".02 .02 .02"/>
        </geometry>
      </collision>

      <visual name='camera_link_visual'>
        <origin xyz="0 0 0" rpy="0 0 0"/>
        <geometry>
          <box size=".02 .02 .02"/>
        </geometry>
      </visual>

    </link>

    <joint type="fixed" name="camera_joint">
      <origin xyz="0 0.021 0.038" rpy="0 0.69 1.5707"/>
      <child link="camera_link"/>
      <parent link="gripper_base"/>
    </joint>

    <joint type="fixed" name="camera_optical_joint">
      <origin xyz="0 0 0" rpy="-1.5707 0 -1.5707"/>
      <child link="camera_link_optical"/>
      <parent link="camera_link"/>
    </joint>

    <link name="camera_link_optical">
    </link>

    <link name='camera_front_link'>
      <pose>0 0 0 0 0 0</pose>
      <collision>
        <origin xyz="0 0 0" rpy="0 0 0"/> 
        <geometry>
          <box size=".02 .02 .02"/>
        </geometry>
      </collision>

      <visual name='camera_front_link_visual'>
        <origin xyz="0 0 0" rpy="0 0 0"/>
        <geometry>
          <box size=".02 .02 .02"/>
        </geometry>
      </visual>

    </link>

    <joint type="fixed" name="camera_front_joint">
      <origin xyz="0 0.8 0.3" rpy="3.1414 -3.40 1.5707"/>
      <child link="camera_front_link"/>
      <parent link="base_link"/>
    </joint>

    <joint type="fixed" name="camera_front_optical_joint">
      <origin xyz="0 0 0" rpy="-1.5707 0 -1.5707"/>
      <child link="camera_front_link_optical"/>
      <parent link="camera_front_link"/>
    </joint>

    <link name="camera_front_link_optical">
    </link>

    <link name='camera_top_link'>
      <pose>0 0 0 0 0 0</pose>
      <collision>
        <origin xyz="0 0 0" rpy="0 0 0"/> 
        <geometry>
          <box size=".02 .02 .02"/>
        </geometry>
      </collision>

      <visual name='camera_top_link_visual'>
        <origin xyz="0 0 0" rpy="0 0 0"/>
        <geometry>
          <box size=".02 .02 .02"/>
        </geometry>
      </visual>

    </link>

    <joint type="fixed" name="camera_top_joint">
      <origin xyz="0 0.2 0.7" rpy="0 1.5707 1.5707"/>
      <child link="camera_top_link"/>
      <parent link="base_link"/>
    </joint>

    <joint type="fixed" name="camera_top_optical_joint">
      <origin xyz="0 0 0" rpy="-1.5707 0 -1.5707"/>
      <child link="camera_top_link_optical"/>
      <parent link="camera_top_link"/>
    </joint>

    <link name="camera_top_link_optical">
    </link>



    <joint name="flange_link_to_gripper_base" type="fixed">
      <parent link="flange_link"/>
      <child link="gripper_base"/>
      <origin xyz="0 0 0.034" rpy="1.579 0 0"/>
    </joint>

    <link name="gripper_left1">
      <xacro:gripper_link_inertial/>
      <visual>
        <geometry>
          <mesh filename="package://avu_description/meshes/gripper_left1.dae" scale="1.0 1.0 2.5"/>
        </geometry>
        <origin xyz="0.039 -0.0133 -0.012" rpy="0 0 0"/>
      </visual>
      <collision>
        <geometry>
          <box size="0.013 0.02 0.0375"/>
        </geometry>
        <origin xyz="0.013 0.042 -0.010" rpy="0 0 0"/>
      </collision>
    </link>

    <link name="gripper_left2">
      <xacro:gripper_link_inertial/>
      <visual>
        <geometry>
          <mesh filename="package://avu_description/meshes/gripper_left2.dae"/>
        </geometry>
        <origin xyz="0.005 -0.0195 -0.012" rpy="0 0 0"/>
      </visual>
      <collision>
        <geometry>
          <box size="0.02 0.02 0.02"/>
        </geometry>
        <origin xyz="-0.025 0.0 -0.010" rpy="0 0 0"/>
      </collision>
    </link>

    <link name="gripper_left3">
      <xacro:gripper_link_inertial/>
      <visual>
        <geometry>
          <mesh filename="package://avu_description/meshes/gripper_left3.dae"/>
        </geometry>
        <origin xyz="0.012 0.0025 -0.012" rpy="0 0 0"/>
      </visual>
      <collision>
        <geometry>
          <box size="0.01 0.01 0.01"/>
        </geometry>
        <origin xyz="-0.014 0.005 0.005" rpy="0 0 0"/>
      </collision>
    </link>

    <link name="gripper_right1">
      <xacro:gripper_link_inertial/>
      <visual>
        <geometry>
          <mesh filename="package://avu_description/meshes/gripper_right1.dae" scale="1.0 1.0 2.5"/>
        </geometry>
        <origin xyz="-0.039 -0.0133 -0.012" rpy="0 0 0"/>
      </visual>
      <collision>
        <geometry>
          <box size="0.013 0.02 0.0375"/>
        </geometry>
        <origin xyz="-0.013 0.042 -0.010" rpy="0 0 0"/>
      </collision>
    </link>

    <link name="gripper_right2">
      <xacro:gripper_link_inertial/>
      <visual>
        <geometry>
          <mesh filename="package://avu_description/meshes/gripper_right2.dae"/>
        </geometry>
        <origin xyz="-0.005 -0.0195 -0.012" rpy="0 0 0"/>
      </visual>
      <collision>
        <geometry>
          <box size="0.02 0.02 0.02"/>
        </geometry>
        <origin xyz="0.025 0.0 -0.010" rpy="0 0 0"/>
      </collision>
    </link>

    <link name="gripper_right3">
      <xacro:gripper_link_inertial/>
      <visual>
        <geometry>
          <mesh filename="package://avu_description/meshes/gripper_right3.dae"/>
        </geometry>
        <origin xyz="-0.012 0.0025 -0.012" rpy="0 0 0"/>
      </visual>
      <collision>
        <geometry>
          <box size="0.01 0.01 0.01"/>
        </geometry>
        <origin xyz="0.014 0.005 0.005" rpy="0 0 0"/>
      </collision>
    </link>

    <joint name="gripper_joint" type="revolute">
      <axis xyz="0 0 1"/>
      <limit effort="${joint_effort}" lower="-0.7" upper="0.15" velocity="${joint_velocity}"/>
      <parent link="gripper_base"/>
      <child link="gripper_left3"/>
      <origin xyz="-0.012 0.005 0" rpy="0 0 0"/>
      <dynamics damping="${joint_damping}" friction="${joint_friction}"/>
    </joint>

    <joint name="gripper_base_to_gripper_left2" type="revolute">
      <axis xyz="0 0 1"/>
      <limit effort="${joint_effort}" lower="-0.8" upper="0.5" velocity="${joint_velocity}"/>
      <parent link="gripper_base"/>
      <child link="gripper_left2"/>
      <origin xyz="-0.005 0.027 0" rpy="0 0 0"/>
      <mimic joint="gripper_joint" multiplier="1.0" offset="0"/>
      <dynamics damping="${joint_damping}" friction="${joint_friction}"/>
    </joint>

    <joint name="gripper_left3_to_gripper_left1" type="revolute">
      <axis xyz="0 0 1"/>
      <limit effort="${joint_effort}" lower="-0.5" upper="0.5" velocity="${joint_velocity}"/>
      <parent link="gripper_left3"/>
      <child link="gripper_left1"/>
      <origin xyz="-0.027 0.016 0" rpy="0 0 0"/>
      <mimic joint="gripper_joint" multiplier="-1.0" offset="0"/>
      <dynamics damping="${joint_damping}" friction="${joint_friction}"/>
    </joint>

    <joint name="gripper_base_to_gripper_right3" type="revolute">
      <axis xyz="0 0 1"/>
      <limit effort="${joint_effort}" lower="-0.15" upper="0.7" velocity="${joint_velocity}"/>
      <parent link="gripper_base"/>
      <child link="gripper_right3"/>
      <origin xyz="0.012 0.005 0" rpy="0 0 0"/>
      <mimic joint="gripper_joint" multiplier="-1.0" offset="0"/>
      <dynamics damping="${joint_damping}" friction="${joint_friction}"/>
    </joint>

    <joint name="gripper_base_to_gripper_right2" type="revolute">
      <axis xyz="0 0 1"/>
      <limit effort="${joint_effort}" lower="-0.5" upper="0.8" velocity="${joint_velocity}"/>
      <parent link="gripper_base"/>
      <child link="gripper_right2"/>
      <origin xyz="0.005 0.027 0" rpy="0 0 0"/>
      <mimic joint="gripper_joint" multiplier="-1.0" offset="0"/>
      <dynamics damping="${joint_damping}" friction="${joint_friction}"/>
    </joint>

    <joint name="gripper_right3_to_gripper_right1" type="revolute">
      <axis xyz="0 0 1"/>
      <limit effort="${joint_effort}" lower="-0.5" upper="0.5" velocity="${joint_velocity}"/>
      <parent link="gripper_right3"/>
      <child link="gripper_right1"/>
      <origin xyz="0.027 0.016 0" rpy="0 0 0"/>
      <mimic joint="gripper_joint" multiplier="1.0" offset="0"/>
      <dynamics damping="${joint_damping}" friction="${joint_friction}"/>
    </joint>

    <link name="end_effector"/>

    <joint name="ee-joint" type="fixed">
      <parent link="gripper_base"/>
      <child link="end_effector"/>
      <origin xyz="0 0.08 0" rpy="0 0 0"/>
    </joint>


    <xacro:material_visual ref_link="link1" ambient="0.5 0.5 0.5 1" diffuse="0.5 0.5 0.5 1" specular="0.5 0.5 0.5 1"/>
    <xacro:material_visual ref_link="link2" ambient="1 1 1 1" diffuse="1 1 1 1" specular="1 1 1 1"/>
    <xacro:material_visual ref_link="link3" ambient="1 1 1 1" diffuse="1 1 1 1" specular="1 1 1 1"/>
    <xacro:material_visual ref_link="link4" ambient="1 1 1 1" diffuse="1 1 1 1" specular="1 1 1 1"/>
    <xacro:material_visual ref_link="link5" ambient="1 1 1 1" diffuse="1 1 1 1" specular="1 1 1 1"/>
    <xacro:material_visual ref_link="link6" ambient="1 1 1 1" diffuse="1 1 1 1" specular="1 1 1 1"/>
    <xacro:material_visual ref_link="flange_link" ambient="0.5 0.5 0.5 1" diffuse="0.5 0.5 0.5 1" specular="0.5 0.5 0.5 1"/>

    
</robot>